2024-06-24 19:42:55,016 INFO    StreamThr :36431 [internal.py:wandb_internal():86] W&B internal server running at pid: 36431, started at: 2024-06-24 19:42:55.015025
2024-06-24 19:42:55,017 DEBUG   HandlerThread:36431 [handler.py:handle_request():146] handle_request: status
2024-06-24 19:42:55,026 INFO    WriterThread:36431 [datastore.py:open_for_write():87] open: ./wandb/run-20240624_194255-6jss0yue/run-6jss0yue.wandb
2024-06-24 19:42:55,027 DEBUG   SenderThread:36431 [sender.py:send():379] send: header
2024-06-24 19:42:55,064 DEBUG   SenderThread:36431 [sender.py:send():379] send: run
2024-06-24 19:42:58,281 INFO    SenderThread:36431 [retry.py:__call__():172] Retry attempt failed:
Traceback (most recent call last):
  File "/Users/devu/anaconda3/envs/npt/lib/python3.8/site-packages/urllib3/connection.py", line 203, in _new_conn
    sock = connection.create_connection(
  File "/Users/devu/anaconda3/envs/npt/lib/python3.8/site-packages/urllib3/util/connection.py", line 60, in create_connection
    for res in socket.getaddrinfo(host, port, family, socket.SOCK_STREAM):
  File "/Users/devu/anaconda3/envs/npt/lib/python3.8/socket.py", line 918, in getaddrinfo
    for res in _socket.getaddrinfo(host, port, family, type, proto, flags):
socket.gaierror: [Errno 8] nodename nor servname provided, or not known

The above exception was the direct cause of the following exception:

Traceback (most recent call last):
  File "/Users/devu/anaconda3/envs/npt/lib/python3.8/site-packages/urllib3/connectionpool.py", line 790, in urlopen
    response = self._make_request(
  File "/Users/devu/anaconda3/envs/npt/lib/python3.8/site-packages/urllib3/connectionpool.py", line 491, in _make_request
    raise new_e
  File "/Users/devu/anaconda3/envs/npt/lib/python3.8/site-packages/urllib3/connectionpool.py", line 467, in _make_request
    self._validate_conn(conn)
  File "/Users/devu/anaconda3/envs/npt/lib/python3.8/site-packages/urllib3/connectionpool.py", line 1096, in _validate_conn
    conn.connect()
  File "/Users/devu/anaconda3/envs/npt/lib/python3.8/site-packages/urllib3/connection.py", line 611, in connect
    self.sock = sock = self._new_conn()
  File "/Users/devu/anaconda3/envs/npt/lib/python3.8/site-packages/urllib3/connection.py", line 210, in _new_conn
    raise NameResolutionError(self.host, self, e) from e
urllib3.exceptions.NameResolutionError: <urllib3.connection.HTTPSConnection object at 0x115cc7ac0>: Failed to resolve 'api.wandb.ai' ([Errno 8] nodename nor servname provided, or not known)

The above exception was the direct cause of the following exception:

Traceback (most recent call last):
  File "/Users/devu/anaconda3/envs/npt/lib/python3.8/site-packages/requests/adapters.py", line 486, in send
    resp = conn.urlopen(
  File "/Users/devu/anaconda3/envs/npt/lib/python3.8/site-packages/urllib3/connectionpool.py", line 844, in urlopen
    retries = retries.increment(
  File "/Users/devu/anaconda3/envs/npt/lib/python3.8/site-packages/urllib3/util/retry.py", line 515, in increment
    raise MaxRetryError(_pool, url, reason) from reason  # type: ignore[arg-type]
urllib3.exceptions.MaxRetryError: HTTPSConnectionPool(host='api.wandb.ai', port=443): Max retries exceeded with url: /graphql (Caused by NameResolutionError("<urllib3.connection.HTTPSConnection object at 0x115cc7ac0>: Failed to resolve 'api.wandb.ai' ([Errno 8] nodename nor servname provided, or not known)"))

During handling of the above exception, another exception occurred:

Traceback (most recent call last):
  File "/Users/devu/anaconda3/envs/npt/lib/python3.8/site-packages/wandb/sdk/lib/retry.py", line 131, in __call__
    result = self._call_fn(*args, **kwargs)
  File "/Users/devu/anaconda3/envs/npt/lib/python3.8/site-packages/wandb/sdk/internal/internal_api.py", line 369, in execute
    return self.client.execute(*args, **kwargs)  # type: ignore
  File "/Users/devu/anaconda3/envs/npt/lib/python3.8/site-packages/wandb/vendor/gql-0.2.0/wandb_gql/client.py", line 52, in execute
    result = self._get_result(document, *args, **kwargs)
  File "/Users/devu/anaconda3/envs/npt/lib/python3.8/site-packages/wandb/vendor/gql-0.2.0/wandb_gql/client.py", line 60, in _get_result
    return self.transport.execute(document, *args, **kwargs)
  File "/Users/devu/anaconda3/envs/npt/lib/python3.8/site-packages/wandb/sdk/lib/gql_request.py", line 58, in execute
    request = self.session.post(self.url, **post_args)
  File "/Users/devu/anaconda3/envs/npt/lib/python3.8/site-packages/requests/sessions.py", line 637, in post
    return self.request("POST", url, data=data, json=json, **kwargs)
  File "/Users/devu/anaconda3/envs/npt/lib/python3.8/site-packages/requests/sessions.py", line 589, in request
    resp = self.send(prep, **send_kwargs)
  File "/Users/devu/anaconda3/envs/npt/lib/python3.8/site-packages/requests/sessions.py", line 703, in send
    r = adapter.send(request, **kwargs)
  File "/Users/devu/anaconda3/envs/npt/lib/python3.8/site-packages/requests/adapters.py", line 519, in send
    raise ConnectionError(e, request=request)
requests.exceptions.ConnectionError: HTTPSConnectionPool(host='api.wandb.ai', port=443): Max retries exceeded with url: /graphql (Caused by NameResolutionError("<urllib3.connection.HTTPSConnection object at 0x115cc7ac0>: Failed to resolve 'api.wandb.ai' ([Errno 8] nodename nor servname provided, or not known)"))
2024-06-24 19:43:00,088 DEBUG   HandlerThread:36431 [handler.py:handle_request():146] handle_request: keepalive
2024-06-24 19:43:05,096 DEBUG   HandlerThread:36431 [handler.py:handle_request():146] handle_request: keepalive
2024-06-24 19:43:10,114 DEBUG   HandlerThread:36431 [handler.py:handle_request():146] handle_request: keepalive
2024-06-24 19:43:15,139 DEBUG   HandlerThread:36431 [handler.py:handle_request():146] handle_request: keepalive
2024-06-24 19:43:20,158 DEBUG   HandlerThread:36431 [handler.py:handle_request():146] handle_request: keepalive
2024-06-24 19:43:25,183 DEBUG   HandlerThread:36431 [handler.py:handle_request():146] handle_request: keepalive
2024-06-24 19:43:30,208 DEBUG   HandlerThread:36431 [handler.py:handle_request():146] handle_request: keepalive
2024-06-24 19:43:35,215 DEBUG   HandlerThread:36431 [handler.py:handle_request():146] handle_request: keepalive
2024-06-24 19:43:40,235 DEBUG   HandlerThread:36431 [handler.py:handle_request():146] handle_request: keepalive
2024-06-24 19:43:45,246 DEBUG   HandlerThread:36431 [handler.py:handle_request():146] handle_request: keepalive
2024-06-24 19:43:50,263 DEBUG   HandlerThread:36431 [handler.py:handle_request():146] handle_request: keepalive
2024-06-24 19:43:55,277 DEBUG   HandlerThread:36431 [handler.py:handle_request():146] handle_request: keepalive
2024-06-24 19:44:00,294 DEBUG   HandlerThread:36431 [handler.py:handle_request():146] handle_request: keepalive
2024-06-24 19:44:05,308 DEBUG   HandlerThread:36431 [handler.py:handle_request():146] handle_request: keepalive
2024-06-24 19:44:10,327 DEBUG   HandlerThread:36431 [handler.py:handle_request():146] handle_request: keepalive
2024-06-24 19:44:15,343 DEBUG   HandlerThread:36431 [handler.py:handle_request():146] handle_request: keepalive
2024-06-24 19:44:20,366 DEBUG   HandlerThread:36431 [handler.py:handle_request():146] handle_request: keepalive
2024-06-24 19:44:25,384 DEBUG   HandlerThread:36431 [handler.py:handle_request():146] handle_request: cancel
2024-06-24 19:44:25,385 DEBUG   HandlerThread:36431 [handler.py:handle_request():146] handle_request: cancel
2024-06-24 19:44:25,386 DEBUG   SenderThread:36431 [sender.py:send():388] Record cancelled: run
2024-06-24 19:44:25,387 DEBUG   HandlerThread:36431 [handler.py:handle_request():146] handle_request: status_report
2024-06-24 19:44:25,419 DEBUG   HandlerThread:36431 [handler.py:handle_request():146] handle_request: shutdown
2024-06-24 19:44:25,419 INFO    HandlerThread:36431 [handler.py:finish():866] shutting down handler
2024-06-24 19:44:26,391 INFO    WriterThread:36431 [datastore.py:close():296] close: ./wandb/run-20240624_194255-6jss0yue/run-6jss0yue.wandb
2024-06-24 19:44:26,392 INFO    SenderThread:36431 [sender.py:finish():1546] shutting down sender
