2024-06-24 19:40:52,014 INFO    StreamThr :36381 [internal.py:wandb_internal():86] W&B internal server running at pid: 36381, started at: 2024-06-24 19:40:52.013442
2024-06-24 19:40:52,015 DEBUG   HandlerThread:36381 [handler.py:handle_request():146] handle_request: status
2024-06-24 19:40:52,025 INFO    WriterThread:36381 [datastore.py:open_for_write():87] open: ./wandb/run-20240624_194051-wk0sa9hy/run-wk0sa9hy.wandb
2024-06-24 19:40:52,026 DEBUG   SenderThread:36381 [sender.py:send():379] send: header
2024-06-24 19:40:52,063 DEBUG   SenderThread:36381 [sender.py:send():379] send: run
2024-06-24 19:40:55,400 INFO    SenderThread:36381 [retry.py:__call__():172] Retry attempt failed:
Traceback (most recent call last):
  File "/Users/devu/anaconda3/envs/npt/lib/python3.8/site-packages/urllib3/connection.py", line 203, in _new_conn
    sock = connection.create_connection(
  File "/Users/devu/anaconda3/envs/npt/lib/python3.8/site-packages/urllib3/util/connection.py", line 60, in create_connection
    for res in socket.getaddrinfo(host, port, family, socket.SOCK_STREAM):
  File "/Users/devu/anaconda3/envs/npt/lib/python3.8/socket.py", line 918, in getaddrinfo
    for res in _socket.getaddrinfo(host, port, family, type, proto, flags):
socket.gaierror: [Errno 8] nodename nor servname provided, or not known

The above exception was the direct cause of the following exception:

Traceback (most recent call last):
  File "/Users/devu/anaconda3/envs/npt/lib/python3.8/site-packages/urllib3/connectionpool.py", line 790, in urlopen
    response = self._make_request(
  File "/Users/devu/anaconda3/envs/npt/lib/python3.8/site-packages/urllib3/connectionpool.py", line 491, in _make_request
    raise new_e
  File "/Users/devu/anaconda3/envs/npt/lib/python3.8/site-packages/urllib3/connectionpool.py", line 467, in _make_request
    self._validate_conn(conn)
  File "/Users/devu/anaconda3/envs/npt/lib/python3.8/site-packages/urllib3/connectionpool.py", line 1096, in _validate_conn
    conn.connect()
  File "/Users/devu/anaconda3/envs/npt/lib/python3.8/site-packages/urllib3/connection.py", line 611, in connect
    self.sock = sock = self._new_conn()
  File "/Users/devu/anaconda3/envs/npt/lib/python3.8/site-packages/urllib3/connection.py", line 210, in _new_conn
    raise NameResolutionError(self.host, self, e) from e
urllib3.exceptions.NameResolutionError: <urllib3.connection.HTTPSConnection object at 0x115f94b20>: Failed to resolve 'api.wandb.ai' ([Errno 8] nodename nor servname provided, or not known)

The above exception was the direct cause of the following exception:

Traceback (most recent call last):
  File "/Users/devu/anaconda3/envs/npt/lib/python3.8/site-packages/requests/adapters.py", line 486, in send
    resp = conn.urlopen(
  File "/Users/devu/anaconda3/envs/npt/lib/python3.8/site-packages/urllib3/connectionpool.py", line 844, in urlopen
    retries = retries.increment(
  File "/Users/devu/anaconda3/envs/npt/lib/python3.8/site-packages/urllib3/util/retry.py", line 515, in increment
    raise MaxRetryError(_pool, url, reason) from reason  # type: ignore[arg-type]
urllib3.exceptions.MaxRetryError: HTTPSConnectionPool(host='api.wandb.ai', port=443): Max retries exceeded with url: /graphql (Caused by NameResolutionError("<urllib3.connection.HTTPSConnection object at 0x115f94b20>: Failed to resolve 'api.wandb.ai' ([Errno 8] nodename nor servname provided, or not known)"))

During handling of the above exception, another exception occurred:

Traceback (most recent call last):
  File "/Users/devu/anaconda3/envs/npt/lib/python3.8/site-packages/wandb/sdk/lib/retry.py", line 131, in __call__
    result = self._call_fn(*args, **kwargs)
  File "/Users/devu/anaconda3/envs/npt/lib/python3.8/site-packages/wandb/sdk/internal/internal_api.py", line 369, in execute
    return self.client.execute(*args, **kwargs)  # type: ignore
  File "/Users/devu/anaconda3/envs/npt/lib/python3.8/site-packages/wandb/vendor/gql-0.2.0/wandb_gql/client.py", line 52, in execute
    result = self._get_result(document, *args, **kwargs)
  File "/Users/devu/anaconda3/envs/npt/lib/python3.8/site-packages/wandb/vendor/gql-0.2.0/wandb_gql/client.py", line 60, in _get_result
    return self.transport.execute(document, *args, **kwargs)
  File "/Users/devu/anaconda3/envs/npt/lib/python3.8/site-packages/wandb/sdk/lib/gql_request.py", line 58, in execute
    request = self.session.post(self.url, **post_args)
  File "/Users/devu/anaconda3/envs/npt/lib/python3.8/site-packages/requests/sessions.py", line 637, in post
    return self.request("POST", url, data=data, json=json, **kwargs)
  File "/Users/devu/anaconda3/envs/npt/lib/python3.8/site-packages/requests/sessions.py", line 589, in request
    resp = self.send(prep, **send_kwargs)
  File "/Users/devu/anaconda3/envs/npt/lib/python3.8/site-packages/requests/sessions.py", line 703, in send
    r = adapter.send(request, **kwargs)
  File "/Users/devu/anaconda3/envs/npt/lib/python3.8/site-packages/requests/adapters.py", line 519, in send
    raise ConnectionError(e, request=request)
requests.exceptions.ConnectionError: HTTPSConnectionPool(host='api.wandb.ai', port=443): Max retries exceeded with url: /graphql (Caused by NameResolutionError("<urllib3.connection.HTTPSConnection object at 0x115f94b20>: Failed to resolve 'api.wandb.ai' ([Errno 8] nodename nor servname provided, or not known)"))
2024-06-24 19:40:57,080 DEBUG   HandlerThread:36381 [handler.py:handle_request():146] handle_request: keepalive
2024-06-24 19:41:02,099 DEBUG   HandlerThread:36381 [handler.py:handle_request():146] handle_request: keepalive
2024-06-24 19:41:07,121 DEBUG   HandlerThread:36381 [handler.py:handle_request():146] handle_request: keepalive
2024-06-24 19:41:12,142 DEBUG   HandlerThread:36381 [handler.py:handle_request():146] handle_request: keepalive
2024-06-24 19:41:17,161 DEBUG   HandlerThread:36381 [handler.py:handle_request():146] handle_request: keepalive
2024-06-24 19:41:22,180 DEBUG   HandlerThread:36381 [handler.py:handle_request():146] handle_request: keepalive
2024-06-24 19:41:27,193 DEBUG   HandlerThread:36381 [handler.py:handle_request():146] handle_request: keepalive
2024-06-24 19:41:32,217 DEBUG   HandlerThread:36381 [handler.py:handle_request():146] handle_request: keepalive
2024-06-24 19:41:37,233 DEBUG   HandlerThread:36381 [handler.py:handle_request():146] handle_request: keepalive
2024-06-24 19:41:42,259 DEBUG   HandlerThread:36381 [handler.py:handle_request():146] handle_request: keepalive
2024-06-24 19:41:42,689 DEBUG   HandlerThread:36381 [handler.py:handle_request():146] handle_request: shutdown
2024-06-24 19:41:42,690 INFO    HandlerThread:36381 [handler.py:finish():866] shutting down handler
2024-06-24 19:41:43,218 INFO    WriterThread:36381 [datastore.py:close():296] close: ./wandb/run-20240624_194051-wk0sa9hy/run-wk0sa9hy.wandb
2024-06-26 19:14:43,302 INFO    SenderThread:36381 [dir_watcher.py:__init__():211] watching files in: ./wandb/run-20240624_194051-wk0sa9hy/files
2024-06-26 19:14:43,304 INFO    SenderThread:36381 [sender.py:_start_run_threads():1124] run started: wk0sa9hy with start time 1719238252.014223
2024-06-26 19:14:43,305 INFO    SenderThread:36381 [sender.py:finish():1546] shutting down sender
2024-06-26 19:14:43,305 INFO    SenderThread:36381 [dir_watcher.py:finish():358] shutting down directory watcher
2024-06-26 19:14:44,308 INFO    SenderThread:36381 [dir_watcher.py:finish():388] scan: ./wandb/run-20240624_194051-wk0sa9hy/files
2024-06-26 19:14:44,310 INFO    SenderThread:36381 [dir_watcher.py:finish():402] scan save: ./wandb/run-20240624_194051-wk0sa9hy/files/config.yaml config.yaml
2024-06-26 19:14:44,311 INFO    SenderThread:36381 [file_pusher.py:finish():172] shutting down file pusher
2024-06-26 19:14:44,311 INFO    SenderThread:36381 [file_pusher.py:join():178] waiting for file pusher
2024-06-26 19:14:45,027 INFO    wandb-upload_0:36381 [upload_job.py:push():131] Uploaded file ./wandb/run-20240624_194051-wk0sa9hy/files/config.yaml
2024-06-26 19:14:45,314 INFO    SenderThread:36381 [file_stream.py:finish():614] file stream finish called
2024-06-26 19:14:45,540 INFO    SenderThread:36381 [file_stream.py:finish():618] file stream finish is done
